[2023-07-05T12:15:12.119+0100] {taskinstance.py:1103} INFO - Dependencies all met for dep_context=non-requeueable deps ti=<TaskInstance: update_current_data_10.extract_current_data scheduled__2023-05-10T17:00:00+00:00 [queued]>
[2023-07-05T12:15:12.127+0100] {taskinstance.py:1103} INFO - Dependencies all met for dep_context=requeueable deps ti=<TaskInstance: update_current_data_10.extract_current_data scheduled__2023-05-10T17:00:00+00:00 [queued]>
[2023-07-05T12:15:12.127+0100] {taskinstance.py:1308} INFO - Starting attempt 1 of 3
[2023-07-05T12:15:12.137+0100] {taskinstance.py:1327} INFO - Executing <Task(PythonOperator): extract_current_data> on 2023-05-10 17:00:00+00:00
[2023-07-05T12:15:12.141+0100] {standard_task_runner.py:57} INFO - Started process 133353 to run task
[2023-07-05T12:15:12.144+0100] {standard_task_runner.py:84} INFO - Running: ['***', 'tasks', 'run', 'update_current_data_10', 'extract_current_data', 'scheduled__2023-05-10T17:00:00+00:00', '--job-id', '1884', '--raw', '--subdir', '/home/haboubi/Desktop/api/API_weather/dags/update_current_dags.py', '--cfg-path', '/tmp/tmpwu640ci9']
[2023-07-05T12:15:12.146+0100] {standard_task_runner.py:85} INFO - Job 1884: Subtask extract_current_data
[2023-07-05T12:15:12.208+0100] {task_command.py:410} INFO - Running <TaskInstance: update_current_data_10.extract_current_data scheduled__2023-05-10T17:00:00+00:00 [running]> on host haboubi-VivoBook-15-ASUS-Laptop-X540UB
[2023-07-05T12:15:12.307+0100] {taskinstance.py:1545} INFO - Exporting env vars: AIRFLOW_CTX_DAG_OWNER='haboubi' AIRFLOW_CTX_DAG_ID='update_current_data_10' AIRFLOW_CTX_TASK_ID='extract_current_data' AIRFLOW_CTX_EXECUTION_DATE='2023-05-10T17:00:00+00:00' AIRFLOW_CTX_TRY_NUMBER='1' AIRFLOW_CTX_DAG_RUN_ID='scheduled__2023-05-10T17:00:00+00:00'
[2023-07-05T12:15:16.877+0100] {taskinstance.py:1824} ERROR - Task failed with exception
Traceback (most recent call last):
  File "/home/haboubi/Desktop/api/API_weather/api_env/lib/python3.10/site-packages/urllib3/connectionpool.py", line 714, in urlopen
    httplib_response = self._make_request(
  File "/home/haboubi/Desktop/api/API_weather/api_env/lib/python3.10/site-packages/urllib3/connectionpool.py", line 466, in _make_request
    six.raise_from(e, None)
  File "<string>", line 3, in raise_from
  File "/home/haboubi/Desktop/api/API_weather/api_env/lib/python3.10/site-packages/urllib3/connectionpool.py", line 461, in _make_request
    httplib_response = conn.getresponse()
  File "/usr/lib/python3.10/http/client.py", line 1374, in getresponse
    response.begin()
  File "/usr/lib/python3.10/http/client.py", line 318, in begin
    version, status, reason = self._read_status()
  File "/usr/lib/python3.10/http/client.py", line 287, in _read_status
    raise RemoteDisconnected("Remote end closed connection without"
http.client.RemoteDisconnected: Remote end closed connection without response

During handling of the above exception, another exception occurred:

Traceback (most recent call last):
  File "/home/haboubi/Desktop/api/API_weather/api_env/lib/python3.10/site-packages/requests/adapters.py", line 486, in send
    resp = conn.urlopen(
  File "/home/haboubi/Desktop/api/API_weather/api_env/lib/python3.10/site-packages/urllib3/connectionpool.py", line 798, in urlopen
    retries = retries.increment(
  File "/home/haboubi/Desktop/api/API_weather/api_env/lib/python3.10/site-packages/urllib3/util/retry.py", line 550, in increment
    raise six.reraise(type(error), error, _stacktrace)
  File "/home/haboubi/Desktop/api/API_weather/api_env/lib/python3.10/site-packages/urllib3/packages/six.py", line 769, in reraise
    raise value.with_traceback(tb)
  File "/home/haboubi/Desktop/api/API_weather/api_env/lib/python3.10/site-packages/urllib3/connectionpool.py", line 714, in urlopen
    httplib_response = self._make_request(
  File "/home/haboubi/Desktop/api/API_weather/api_env/lib/python3.10/site-packages/urllib3/connectionpool.py", line 466, in _make_request
    six.raise_from(e, None)
  File "<string>", line 3, in raise_from
  File "/home/haboubi/Desktop/api/API_weather/api_env/lib/python3.10/site-packages/urllib3/connectionpool.py", line 461, in _make_request
    httplib_response = conn.getresponse()
  File "/usr/lib/python3.10/http/client.py", line 1374, in getresponse
    response.begin()
  File "/usr/lib/python3.10/http/client.py", line 318, in begin
    version, status, reason = self._read_status()
  File "/usr/lib/python3.10/http/client.py", line 287, in _read_status
    raise RemoteDisconnected("Remote end closed connection without"
urllib3.exceptions.ProtocolError: ('Connection aborted.', RemoteDisconnected('Remote end closed connection without response'))

During handling of the above exception, another exception occurred:

Traceback (most recent call last):
  File "/home/haboubi/Desktop/api/API_weather/api_env/lib/python3.10/site-packages/airflow/operators/python.py", line 181, in execute
    return_value = self.execute_callable()
  File "/home/haboubi/Desktop/api/API_weather/api_env/lib/python3.10/site-packages/airflow/operators/python.py", line 198, in execute_callable
    return self.python_callable(*self.op_args, **self.op_kwargs)
  File "/home/haboubi/Desktop/api/API_weather/dags/update_current_dags.py", line 30, in extract_data
    save_current_pd_csv()
  File "/home/haboubi/Desktop/api/API_weather/./dags/current_data_fetch.py", line 100, in save_current_pd_csv
    df,location_df=create_current_data_pd_total(location_df,city=c)
  File "/home/haboubi/Desktop/api/API_weather/./dags/current_data_fetch.py", line 45, in create_current_data_pd_total
    r=requests.get(historical,params=param)
  File "/home/haboubi/Desktop/api/API_weather/api_env/lib/python3.10/site-packages/requests/api.py", line 73, in get
    return request("get", url, params=params, **kwargs)
  File "/home/haboubi/Desktop/api/API_weather/api_env/lib/python3.10/site-packages/requests/api.py", line 59, in request
    return session.request(method=method, url=url, **kwargs)
  File "/home/haboubi/Desktop/api/API_weather/api_env/lib/python3.10/site-packages/requests/sessions.py", line 589, in request
    resp = self.send(prep, **send_kwargs)
  File "/home/haboubi/Desktop/api/API_weather/api_env/lib/python3.10/site-packages/requests/sessions.py", line 725, in send
    history = [resp for resp in gen]
  File "/home/haboubi/Desktop/api/API_weather/api_env/lib/python3.10/site-packages/requests/sessions.py", line 725, in <listcomp>
    history = [resp for resp in gen]
  File "/home/haboubi/Desktop/api/API_weather/api_env/lib/python3.10/site-packages/requests/sessions.py", line 266, in resolve_redirects
    resp = self.send(
  File "/home/haboubi/Desktop/api/API_weather/api_env/lib/python3.10/site-packages/requests/sessions.py", line 703, in send
    r = adapter.send(request, **kwargs)
  File "/home/haboubi/Desktop/api/API_weather/api_env/lib/python3.10/site-packages/requests/adapters.py", line 501, in send
    raise ConnectionError(err, request=request)
requests.exceptions.ConnectionError: ('Connection aborted.', RemoteDisconnected('Remote end closed connection without response'))
[2023-07-05T12:15:16.924+0100] {taskinstance.py:1345} INFO - Marking task as UP_FOR_RETRY. dag_id=update_current_data_10, task_id=extract_current_data, execution_date=20230510T170000, start_date=20230705T111512, end_date=20230705T111516
[2023-07-05T12:15:16.939+0100] {standard_task_runner.py:104} ERROR - Failed to execute job 1884 for task extract_current_data (('Connection aborted.', RemoteDisconnected('Remote end closed connection without response')); 133353)
[2023-07-05T12:15:16.947+0100] {local_task_job_runner.py:225} INFO - Task exited with return code 1
[2023-07-05T12:15:16.975+0100] {taskinstance.py:2653} INFO - 0 downstream tasks scheduled from follow-on schedule check
