[2023-07-07T04:45:46.374+0100] {taskinstance.py:1103} INFO - Dependencies all met for dep_context=non-requeueable deps ti=<TaskInstance: update_current_data_10.extract_current_data scheduled__2023-06-27T12:20:00+00:00 [queued]>
[2023-07-07T04:45:46.387+0100] {taskinstance.py:1103} INFO - Dependencies all met for dep_context=requeueable deps ti=<TaskInstance: update_current_data_10.extract_current_data scheduled__2023-06-27T12:20:00+00:00 [queued]>
[2023-07-07T04:45:46.388+0100] {taskinstance.py:1308} INFO - Starting attempt 1 of 3
[2023-07-07T04:45:46.403+0100] {taskinstance.py:1327} INFO - Executing <Task(PythonOperator): extract_current_data> on 2023-06-27 12:20:00+00:00
[2023-07-07T04:45:46.408+0100] {standard_task_runner.py:57} INFO - Started process 1017137 to run task
[2023-07-07T04:45:46.413+0100] {standard_task_runner.py:84} INFO - Running: ['***', 'tasks', 'run', 'update_current_data_10', 'extract_current_data', 'scheduled__2023-06-27T12:20:00+00:00', '--job-id', '16185', '--raw', '--subdir', '/home/haboubi/Desktop/api/API_weather/dags/update_current_dags.py', '--cfg-path', '/tmp/tmpukvue09f']
[2023-07-07T04:45:46.415+0100] {standard_task_runner.py:85} INFO - Job 16185: Subtask extract_current_data
[2023-07-07T04:45:46.492+0100] {task_command.py:410} INFO - Running <TaskInstance: update_current_data_10.extract_current_data scheduled__2023-06-27T12:20:00+00:00 [running]> on host haboubi-VivoBook-15-ASUS-Laptop-X540UB
[2023-07-07T04:45:46.621+0100] {taskinstance.py:1545} INFO - Exporting env vars: AIRFLOW_CTX_DAG_OWNER='haboubi' AIRFLOW_CTX_DAG_ID='update_current_data_10' AIRFLOW_CTX_TASK_ID='extract_current_data' AIRFLOW_CTX_EXECUTION_DATE='2023-06-27T12:20:00+00:00' AIRFLOW_CTX_TRY_NUMBER='1' AIRFLOW_CTX_DAG_RUN_ID='scheduled__2023-06-27T12:20:00+00:00'
[2023-07-07T04:45:46.626+0100] {taskinstance.py:1824} ERROR - Task failed with exception
Traceback (most recent call last):
  File "/home/haboubi/Desktop/api/API_weather/api_env/lib/python3.10/site-packages/airflow/operators/python.py", line 181, in execute
    return_value = self.execute_callable()
  File "/home/haboubi/Desktop/api/API_weather/api_env/lib/python3.10/site-packages/airflow/operators/python.py", line 198, in execute_callable
    return self.python_callable(*self.op_args, **self.op_kwargs)
  File "/home/haboubi/Desktop/api/API_weather/dags/update_current_dags.py", line 32, in extract_data
    save_current_pd_csv()
  File "/home/haboubi/Desktop/api/API_weather/./dags/current_data_fetch.py", line 78, in save_current_pd_csv
    for c in city:
NameError: name 'city' is not defined
[2023-07-07T04:45:46.645+0100] {taskinstance.py:1345} INFO - Marking task as UP_FOR_RETRY. dag_id=update_current_data_10, task_id=extract_current_data, execution_date=20230627T122000, start_date=20230707T034546, end_date=20230707T034546
[2023-07-07T04:45:46.658+0100] {standard_task_runner.py:104} ERROR - Failed to execute job 16185 for task extract_current_data (name 'city' is not defined; 1017137)
[2023-07-07T04:45:46.705+0100] {local_task_job_runner.py:225} INFO - Task exited with return code 1
[2023-07-07T04:45:46.786+0100] {taskinstance.py:2653} INFO - 0 downstream tasks scheduled from follow-on schedule check
