[2023-07-02T09:47:08.901+0100] {taskinstance.py:1103} INFO - Dependencies all met for dep_context=non-requeueable deps ti=<TaskInstance: init_db.load_data manual__2023-07-02T08:41:01.824190+00:00 [queued]>
[2023-07-02T09:47:08.916+0100] {taskinstance.py:1103} INFO - Dependencies all met for dep_context=requeueable deps ti=<TaskInstance: init_db.load_data manual__2023-07-02T08:41:01.824190+00:00 [queued]>
[2023-07-02T09:47:08.916+0100] {taskinstance.py:1308} INFO - Starting attempt 2 of 2
[2023-07-02T09:47:08.933+0100] {taskinstance.py:1327} INFO - Executing <Task(PythonOperator): load_data> on 2023-07-02 08:41:01.824190+00:00
[2023-07-02T09:47:08.937+0100] {standard_task_runner.py:57} INFO - Started process 19814 to run task
[2023-07-02T09:47:08.942+0100] {standard_task_runner.py:84} INFO - Running: ['***', 'tasks', 'run', 'init_db', 'load_data', 'manual__2023-07-02T08:41:01.824190+00:00', '--job-id', '18', '--raw', '--subdir', '/home/haboubi/Desktop/api/API_weather/dags/init_db.py', '--cfg-path', '/tmp/tmpa3td0b2g']
[2023-07-02T09:47:08.944+0100] {standard_task_runner.py:85} INFO - Job 18: Subtask load_data
[2023-07-02T09:47:09.024+0100] {task_command.py:410} INFO - Running <TaskInstance: init_db.load_data manual__2023-07-02T08:41:01.824190+00:00 [running]> on host haboubi-VivoBook-15-ASUS-Laptop-X540UB
[2023-07-02T09:47:09.134+0100] {taskinstance.py:1545} INFO - Exporting env vars: AIRFLOW_CTX_DAG_OWNER='***' AIRFLOW_CTX_DAG_ID='init_db' AIRFLOW_CTX_TASK_ID='load_data' AIRFLOW_CTX_EXECUTION_DATE='2023-07-02T08:41:01.824190+00:00' AIRFLOW_CTX_TRY_NUMBER='2' AIRFLOW_CTX_DAG_RUN_ID='manual__2023-07-02T08:41:01.824190+00:00'
[2023-07-02T09:47:09.151+0100] {logging_mixin.py:149} INFO - sdqqqqqqqqqqqqqq None
[2023-07-02T09:47:09.193+0100] {logging_mixin.py:149} INFO - <class 'numpy.float64'>
[2023-07-02T09:47:09.194+0100] {taskinstance.py:1824} ERROR - Task failed with exception
Traceback (most recent call last):
  File "/home/haboubi/Desktop/api/API_weather/api_env/lib/python3.10/site-packages/airflow/operators/python.py", line 181, in execute
    return_value = self.execute_callable()
  File "/home/haboubi/Desktop/api/API_weather/api_env/lib/python3.10/site-packages/airflow/operators/python.py", line 198, in execute_callable
    return self.python_callable(*self.op_args, **self.op_kwargs)
  File "/home/haboubi/Desktop/api/API_weather/dags/init_db.py", line 24, in load_data
    locs=location_fill_liste()
  File "/home/haboubi/Desktop/api/API_weather/./dags/ddd.py", line 24, in location_fill_liste
    loc=fill_location_data(loc)
  File "/home/haboubi/Desktop/api/API_weather/./dags/ddd.py", line 13, in fill_location_data
    df=pd.read_csv(file_name,sep='\t')
  File "/home/haboubi/Desktop/api/API_weather/api_env/lib/python3.10/site-packages/pandas/io/parsers/readers.py", line 912, in read_csv
    return _read(filepath_or_buffer, kwds)
  File "/home/haboubi/Desktop/api/API_weather/api_env/lib/python3.10/site-packages/pandas/io/parsers/readers.py", line 577, in _read
    parser = TextFileReader(filepath_or_buffer, **kwds)
  File "/home/haboubi/Desktop/api/API_weather/api_env/lib/python3.10/site-packages/pandas/io/parsers/readers.py", line 1407, in __init__
    self._engine = self._make_engine(f, self.engine)
  File "/home/haboubi/Desktop/api/API_weather/api_env/lib/python3.10/site-packages/pandas/io/parsers/readers.py", line 1661, in _make_engine
    self.handles = get_handle(
  File "/home/haboubi/Desktop/api/API_weather/api_env/lib/python3.10/site-packages/pandas/io/common.py", line 859, in get_handle
    handle = open(
FileNotFoundError: [Errno 2] No such file or directory: './city_hist/Paris.csv'
[2023-07-02T09:47:09.221+0100] {taskinstance.py:1345} INFO - Marking task as FAILED. dag_id=init_db, task_id=load_data, execution_date=20230702T084101, start_date=20230702T084708, end_date=20230702T084709
[2023-07-02T09:47:09.239+0100] {standard_task_runner.py:104} ERROR - Failed to execute job 18 for task load_data ([Errno 2] No such file or directory: './city_hist/Paris.csv'; 19814)
[2023-07-02T09:47:09.274+0100] {local_task_job_runner.py:225} INFO - Task exited with return code 1
[2023-07-02T09:47:09.322+0100] {taskinstance.py:2653} INFO - 0 downstream tasks scheduled from follow-on schedule check
