[2023-07-03T16:26:27.488+0100] {taskinstance.py:1103} INFO - Dependencies all met for dep_context=non-requeueable deps ti=<TaskInstance: updated_day_hist.load_updated_data manual__2023-07-03T15:23:44.831685+00:00 [queued]>
[2023-07-03T16:26:27.499+0100] {taskinstance.py:1103} INFO - Dependencies all met for dep_context=requeueable deps ti=<TaskInstance: updated_day_hist.load_updated_data manual__2023-07-03T15:23:44.831685+00:00 [queued]>
[2023-07-03T16:26:27.499+0100] {taskinstance.py:1308} INFO - Starting attempt 1 of 3
[2023-07-03T16:26:27.512+0100] {taskinstance.py:1327} INFO - Executing <Task(PythonOperator): load_updated_data> on 2023-07-03 15:23:44.831685+00:00
[2023-07-03T16:26:27.516+0100] {standard_task_runner.py:57} INFO - Started process 15470 to run task
[2023-07-03T16:26:27.519+0100] {standard_task_runner.py:84} INFO - Running: ['***', 'tasks', 'run', 'updated_day_hist', 'load_updated_data', 'manual__2023-07-03T15:23:44.831685+00:00', '--job-id', '59', '--raw', '--subdir', '/home/haboubi/Desktop/api/API_weather/dags/update_day_hist.py', '--cfg-path', '/tmp/tmpcvzcfffs']
[2023-07-03T16:26:27.521+0100] {standard_task_runner.py:85} INFO - Job 59: Subtask load_updated_data
[2023-07-03T16:26:27.595+0100] {task_command.py:410} INFO - Running <TaskInstance: updated_day_hist.load_updated_data manual__2023-07-03T15:23:44.831685+00:00 [running]> on host haboubi-VivoBook-15-ASUS-Laptop-X540UB
[2023-07-03T16:26:27.700+0100] {taskinstance.py:1545} INFO - Exporting env vars: AIRFLOW_CTX_DAG_OWNER='haboubi' AIRFLOW_CTX_DAG_ID='updated_day_hist' AIRFLOW_CTX_TASK_ID='load_updated_data' AIRFLOW_CTX_EXECUTION_DATE='2023-07-03T15:23:44.831685+00:00' AIRFLOW_CTX_TRY_NUMBER='1' AIRFLOW_CTX_DAG_RUN_ID='manual__2023-07-03T15:23:44.831685+00:00'
[2023-07-03T16:26:27.712+0100] {taskinstance.py:1824} ERROR - Task failed with exception
Traceback (most recent call last):
  File "/home/haboubi/Desktop/api/API_weather/api_env/lib/python3.10/site-packages/airflow/operators/python.py", line 181, in execute
    return_value = self.execute_callable()
  File "/home/haboubi/Desktop/api/API_weather/api_env/lib/python3.10/site-packages/airflow/operators/python.py", line 198, in execute_callable
    return self.python_callable(*self.op_args, **self.op_kwargs)
  File "/home/haboubi/Desktop/api/API_weather/dags/update_day_hist.py", line 47, in load_updated_data_db
    loc=session.query(Location).filter_by(Location.name==locations_csv.iloc[i]['name']).first()
TypeError: Query.filter_by() takes 1 positional argument but 2 were given
[2023-07-03T16:26:27.728+0100] {taskinstance.py:1345} INFO - Marking task as UP_FOR_RETRY. dag_id=updated_day_hist, task_id=load_updated_data, execution_date=20230703T152344, start_date=20230703T152627, end_date=20230703T152627
[2023-07-03T16:26:27.738+0100] {standard_task_runner.py:104} ERROR - Failed to execute job 59 for task load_updated_data (Query.filter_by() takes 1 positional argument but 2 were given; 15470)
[2023-07-03T16:26:27.771+0100] {local_task_job_runner.py:225} INFO - Task exited with return code 1
[2023-07-03T16:26:27.801+0100] {taskinstance.py:2653} INFO - 0 downstream tasks scheduled from follow-on schedule check
