[2023-07-02T09:53:31.350+0100] {taskinstance.py:1103} INFO - Dependencies all met for dep_context=non-requeueable deps ti=<TaskInstance: init_db.extract_data_id manual__2023-07-02T08:53:27.601141+00:00 [queued]>
[2023-07-02T09:53:31.360+0100] {taskinstance.py:1103} INFO - Dependencies all met for dep_context=requeueable deps ti=<TaskInstance: init_db.extract_data_id manual__2023-07-02T08:53:27.601141+00:00 [queued]>
[2023-07-02T09:53:31.360+0100] {taskinstance.py:1308} INFO - Starting attempt 1 of 1
[2023-07-02T09:53:31.375+0100] {taskinstance.py:1327} INFO - Executing <Task(PythonOperator): extract_data_id> on 2023-07-02 08:53:27.601141+00:00
[2023-07-02T09:53:31.379+0100] {standard_task_runner.py:57} INFO - Started process 22160 to run task
[2023-07-02T09:53:31.382+0100] {standard_task_runner.py:84} INFO - Running: ['***', 'tasks', 'run', 'init_db', 'extract_data_id', 'manual__2023-07-02T08:53:27.601141+00:00', '--job-id', '22', '--raw', '--subdir', '/home/haboubi/Desktop/api/API_weather/dags/init_db.py', '--cfg-path', '/tmp/tmpcirh8oue']
[2023-07-02T09:53:31.383+0100] {standard_task_runner.py:85} INFO - Job 22: Subtask extract_data_id
[2023-07-02T09:53:31.477+0100] {task_command.py:410} INFO - Running <TaskInstance: init_db.extract_data_id manual__2023-07-02T08:53:27.601141+00:00 [running]> on host haboubi-VivoBook-15-ASUS-Laptop-X540UB
[2023-07-02T09:53:31.615+0100] {taskinstance.py:1545} INFO - Exporting env vars: AIRFLOW_CTX_DAG_OWNER='***' AIRFLOW_CTX_DAG_ID='init_db' AIRFLOW_CTX_TASK_ID='extract_data_id' AIRFLOW_CTX_EXECUTION_DATE='2023-07-02T08:53:27.601141+00:00' AIRFLOW_CTX_TRY_NUMBER='1' AIRFLOW_CTX_DAG_RUN_ID='manual__2023-07-02T08:53:27.601141+00:00'
[2023-07-02T09:53:38.145+0100] {taskinstance.py:1824} ERROR - Task failed with exception
Traceback (most recent call last):
  File "/home/haboubi/Desktop/api/API_weather/api_env/lib/python3.10/site-packages/airflow/operators/python.py", line 181, in execute
    return_value = self.execute_callable()
  File "/home/haboubi/Desktop/api/API_weather/api_env/lib/python3.10/site-packages/airflow/operators/python.py", line 198, in execute_callable
    return self.python_callable(*self.op_args, **self.op_kwargs)
  File "/home/haboubi/Desktop/api/API_weather/./dags/hist_day_data_fetch.py", line 124, in save_pd_csv
    df.to_csv(name, sep='\t', index=False,header=True)
  File "/home/haboubi/Desktop/api/API_weather/api_env/lib/python3.10/site-packages/pandas/core/generic.py", line 3772, in to_csv
    return DataFrameRenderer(formatter).to_csv(
  File "/home/haboubi/Desktop/api/API_weather/api_env/lib/python3.10/site-packages/pandas/io/formats/format.py", line 1186, in to_csv
    csv_formatter.save()
  File "/home/haboubi/Desktop/api/API_weather/api_env/lib/python3.10/site-packages/pandas/io/formats/csvs.py", line 240, in save
    with get_handle(
  File "/home/haboubi/Desktop/api/API_weather/api_env/lib/python3.10/site-packages/pandas/io/common.py", line 737, in get_handle
    check_parent_directory(str(handle))
  File "/home/haboubi/Desktop/api/API_weather/api_env/lib/python3.10/site-packages/pandas/io/common.py", line 600, in check_parent_directory
    raise OSError(rf"Cannot save file into a non-existent directory: '{parent}'")
OSError: Cannot save file into a non-existent directory: 'city_hist'
[2023-07-02T09:53:38.171+0100] {taskinstance.py:1345} INFO - Marking task as FAILED. dag_id=init_db, task_id=extract_data_id, execution_date=20230702T085327, start_date=20230702T085331, end_date=20230702T085338
[2023-07-02T09:53:38.183+0100] {standard_task_runner.py:104} ERROR - Failed to execute job 22 for task extract_data_id (Cannot save file into a non-existent directory: 'city_hist'; 22160)
[2023-07-02T09:53:38.194+0100] {local_task_job_runner.py:225} INFO - Task exited with return code 1
[2023-07-02T09:53:38.227+0100] {taskinstance.py:2653} INFO - 0 downstream tasks scheduled from follow-on schedule check
