[2023-07-05T11:13:34.757+0100] {taskinstance.py:1103} INFO - Dependencies all met for dep_context=non-requeueable deps ti=<TaskInstance: update_current_data_10.load_current_data manual__2023-07-05T10:12:39.935071+00:00 [queued]>
[2023-07-05T11:13:34.766+0100] {taskinstance.py:1103} INFO - Dependencies all met for dep_context=requeueable deps ti=<TaskInstance: update_current_data_10.load_current_data manual__2023-07-05T10:12:39.935071+00:00 [queued]>
[2023-07-05T11:13:34.766+0100] {taskinstance.py:1308} INFO - Starting attempt 1 of 3
[2023-07-05T11:13:34.778+0100] {taskinstance.py:1327} INFO - Executing <Task(PythonOperator): load_current_data> on 2023-07-05 10:12:39.935071+00:00
[2023-07-05T11:13:34.783+0100] {standard_task_runner.py:57} INFO - Started process 80236 to run task
[2023-07-05T11:13:34.787+0100] {standard_task_runner.py:84} INFO - Running: ['***', 'tasks', 'run', 'update_current_data_10', 'load_current_data', 'manual__2023-07-05T10:12:39.935071+00:00', '--job-id', '852', '--raw', '--subdir', '/home/haboubi/Desktop/api/API_weather/dags/update_current_dags.py', '--cfg-path', '/tmp/tmp62o8idzi']
[2023-07-05T11:13:34.789+0100] {standard_task_runner.py:85} INFO - Job 852: Subtask load_current_data
[2023-07-05T11:13:34.856+0100] {task_command.py:410} INFO - Running <TaskInstance: update_current_data_10.load_current_data manual__2023-07-05T10:12:39.935071+00:00 [running]> on host haboubi-VivoBook-15-ASUS-Laptop-X540UB
[2023-07-05T11:13:34.963+0100] {taskinstance.py:1545} INFO - Exporting env vars: AIRFLOW_CTX_DAG_OWNER='haboubi' AIRFLOW_CTX_DAG_ID='update_current_data_10' AIRFLOW_CTX_TASK_ID='load_current_data' AIRFLOW_CTX_EXECUTION_DATE='2023-07-05T10:12:39.935071+00:00' AIRFLOW_CTX_TRY_NUMBER='1' AIRFLOW_CTX_DAG_RUN_ID='manual__2023-07-05T10:12:39.935071+00:00'
[2023-07-05T11:13:34.982+0100] {logging_mixin.py:149} INFO - ['Paris', datetime.date(2023, 7, 4)]
[2023-07-05T11:13:35.013+0100] {taskinstance.py:1824} ERROR - Task failed with exception
Traceback (most recent call last):
  File "/home/haboubi/Desktop/api/API_weather/api_env/lib/python3.10/site-packages/airflow/operators/python.py", line 181, in execute
    return_value = self.execute_callable()
  File "/home/haboubi/Desktop/api/API_weather/api_env/lib/python3.10/site-packages/airflow/operators/python.py", line 198, in execute_callable
    return self.python_callable(*self.op_args, **self.op_kwargs)
  File "/home/haboubi/Desktop/api/API_weather/dags/update_current_dags.py", line 55, in load_updated_data_db
    loc=update_location_entite(loc)
  File "/home/haboubi/Desktop/api/API_weather/dags/update_current_dags.py", line 40, in update_location_entite
    type(datetime(current.date))
TypeError: 'str' object cannot be interpreted as an integer
[2023-07-05T11:13:35.030+0100] {taskinstance.py:1345} INFO - Marking task as UP_FOR_RETRY. dag_id=update_current_data_10, task_id=load_current_data, execution_date=20230705T101239, start_date=20230705T101334, end_date=20230705T101335
[2023-07-05T11:13:35.041+0100] {standard_task_runner.py:104} ERROR - Failed to execute job 852 for task load_current_data ('str' object cannot be interpreted as an integer; 80236)
[2023-07-05T11:13:35.079+0100] {local_task_job_runner.py:225} INFO - Task exited with return code 1
[2023-07-05T11:13:35.113+0100] {taskinstance.py:2653} INFO - 0 downstream tasks scheduled from follow-on schedule check
