[2023-07-07T05:16:53.922+0100] {taskinstance.py:1103} INFO - Dependencies all met for dep_context=non-requeueable deps ti=<TaskInstance: update_current_data_10.extract_current_data scheduled__2023-06-29T03:00:00+00:00 [queued]>
[2023-07-07T05:16:53.931+0100] {taskinstance.py:1103} INFO - Dependencies all met for dep_context=requeueable deps ti=<TaskInstance: update_current_data_10.extract_current_data scheduled__2023-06-29T03:00:00+00:00 [queued]>
[2023-07-07T05:16:53.931+0100] {taskinstance.py:1308} INFO - Starting attempt 3 of 3
[2023-07-07T05:16:53.943+0100] {taskinstance.py:1327} INFO - Executing <Task(PythonOperator): extract_current_data> on 2023-06-29 03:00:00+00:00
[2023-07-07T05:16:53.947+0100] {standard_task_runner.py:57} INFO - Started process 1041482 to run task
[2023-07-07T05:16:53.950+0100] {standard_task_runner.py:84} INFO - Running: ['***', 'tasks', 'run', 'update_current_data_10', 'extract_current_data', 'scheduled__2023-06-29T03:00:00+00:00', '--job-id', '16689', '--raw', '--subdir', '/home/haboubi/Desktop/api/API_weather/dags/update_current_dags.py', '--cfg-path', '/tmp/tmpi4gs3ngg']
[2023-07-07T05:16:53.951+0100] {standard_task_runner.py:85} INFO - Job 16689: Subtask extract_current_data
[2023-07-07T05:16:54.012+0100] {task_command.py:410} INFO - Running <TaskInstance: update_current_data_10.extract_current_data scheduled__2023-06-29T03:00:00+00:00 [running]> on host haboubi-VivoBook-15-ASUS-Laptop-X540UB
[2023-07-07T05:16:54.122+0100] {taskinstance.py:1545} INFO - Exporting env vars: AIRFLOW_CTX_DAG_OWNER='haboubi' AIRFLOW_CTX_DAG_ID='update_current_data_10' AIRFLOW_CTX_TASK_ID='extract_current_data' AIRFLOW_CTX_EXECUTION_DATE='2023-06-29T03:00:00+00:00' AIRFLOW_CTX_TRY_NUMBER='3' AIRFLOW_CTX_DAG_RUN_ID='scheduled__2023-06-29T03:00:00+00:00'
[2023-07-07T05:16:54.336+0100] {taskinstance.py:1824} ERROR - Task failed with exception
Traceback (most recent call last):
  File "/home/haboubi/Desktop/api/API_weather/api_env/lib/python3.10/site-packages/airflow/operators/python.py", line 181, in execute
    return_value = self.execute_callable()
  File "/home/haboubi/Desktop/api/API_weather/api_env/lib/python3.10/site-packages/airflow/operators/python.py", line 198, in execute_callable
    return self.python_callable(*self.op_args, **self.op_kwargs)
  File "/home/haboubi/Desktop/api/API_weather/dags/update_current_dags.py", line 32, in extract_data
    save_current_pd_csv()
  File "/home/haboubi/Desktop/api/API_weather/./dags/current_data_fetch.py", line 79, in save_current_pd_csv
    name='./'+directory+'/'+location_df.iloc[-1]['name']+ '.csv'
  File "/home/haboubi/Desktop/api/API_weather/api_env/lib/python3.10/site-packages/pandas/core/indexing.py", line 1103, in __getitem__
    return self._getitem_axis(maybe_callable, axis=axis)
  File "/home/haboubi/Desktop/api/API_weather/api_env/lib/python3.10/site-packages/pandas/core/indexing.py", line 1656, in _getitem_axis
    self._validate_integer(key, axis)
  File "/home/haboubi/Desktop/api/API_weather/api_env/lib/python3.10/site-packages/pandas/core/indexing.py", line 1589, in _validate_integer
    raise IndexError("single positional indexer is out-of-bounds")
IndexError: single positional indexer is out-of-bounds
[2023-07-07T05:16:54.382+0100] {taskinstance.py:1345} INFO - Marking task as FAILED. dag_id=update_current_data_10, task_id=extract_current_data, execution_date=20230629T030000, start_date=20230707T041653, end_date=20230707T041654
[2023-07-07T05:16:54.399+0100] {standard_task_runner.py:104} ERROR - Failed to execute job 16689 for task extract_current_data (single positional indexer is out-of-bounds; 1041482)
[2023-07-07T05:16:54.442+0100] {local_task_job_runner.py:225} INFO - Task exited with return code 1
[2023-07-07T05:16:54.481+0100] {taskinstance.py:2653} INFO - 0 downstream tasks scheduled from follow-on schedule check
