[2023-07-03T16:36:52.354+0100] {taskinstance.py:1103} INFO - Dependencies all met for dep_context=non-requeueable deps ti=<TaskInstance: updated_day_hist.load_updated_data manual__2023-07-03T15:35:31.838573+00:00 [queued]>
[2023-07-03T16:36:52.362+0100] {taskinstance.py:1103} INFO - Dependencies all met for dep_context=requeueable deps ti=<TaskInstance: updated_day_hist.load_updated_data manual__2023-07-03T15:35:31.838573+00:00 [queued]>
[2023-07-03T16:36:52.362+0100] {taskinstance.py:1308} INFO - Starting attempt 2 of 3
[2023-07-03T16:36:52.374+0100] {taskinstance.py:1327} INFO - Executing <Task(PythonOperator): load_updated_data> on 2023-07-03 15:35:31.838573+00:00
[2023-07-03T16:36:52.378+0100] {standard_task_runner.py:57} INFO - Started process 18079 to run task
[2023-07-03T16:36:52.381+0100] {standard_task_runner.py:84} INFO - Running: ['***', 'tasks', 'run', 'updated_day_hist', 'load_updated_data', 'manual__2023-07-03T15:35:31.838573+00:00', '--job-id', '74', '--raw', '--subdir', '/home/haboubi/Desktop/api/API_weather/dags/update_day_hist.py', '--cfg-path', '/tmp/tmpz48s2ypd']
[2023-07-03T16:36:52.382+0100] {standard_task_runner.py:85} INFO - Job 74: Subtask load_updated_data
[2023-07-03T16:36:52.447+0100] {task_command.py:410} INFO - Running <TaskInstance: updated_day_hist.load_updated_data manual__2023-07-03T15:35:31.838573+00:00 [running]> on host haboubi-VivoBook-15-ASUS-Laptop-X540UB
[2023-07-03T16:36:52.547+0100] {taskinstance.py:1545} INFO - Exporting env vars: AIRFLOW_CTX_DAG_OWNER='haboubi' AIRFLOW_CTX_DAG_ID='updated_day_hist' AIRFLOW_CTX_TASK_ID='load_updated_data' AIRFLOW_CTX_EXECUTION_DATE='2023-07-03T15:35:31.838573+00:00' AIRFLOW_CTX_TRY_NUMBER='2' AIRFLOW_CTX_DAG_RUN_ID='manual__2023-07-03T15:35:31.838573+00:00'
[2023-07-03T16:36:52.554+0100] {logging_mixin.py:149} INFO - debug prb: Paris
[2023-07-03T16:36:52.579+0100] {taskinstance.py:1824} ERROR - Task failed with exception
Traceback (most recent call last):
  File "/home/haboubi/Desktop/api/API_weather/api_env/lib/python3.10/site-packages/airflow/operators/python.py", line 181, in execute
    return_value = self.execute_callable()
  File "/home/haboubi/Desktop/api/API_weather/api_env/lib/python3.10/site-packages/airflow/operators/python.py", line 198, in execute_callable
    return self.python_callable(*self.op_args, **self.op_kwargs)
  File "/home/haboubi/Desktop/api/API_weather/dags/update_day_hist.py", line 49, in load_updated_data_db
    loc=update_location_entite(loc)
  File "/home/haboubi/Desktop/api/API_weather/dags/update_day_hist.py", line 32, in update_location_entite
    directory='city_hist_updated/'+loc['name']+'.csv'
TypeError: 'Location' object is not subscriptable
[2023-07-03T16:36:52.594+0100] {taskinstance.py:1345} INFO - Marking task as UP_FOR_RETRY. dag_id=updated_day_hist, task_id=load_updated_data, execution_date=20230703T153531, start_date=20230703T153652, end_date=20230703T153652
[2023-07-03T16:36:52.604+0100] {standard_task_runner.py:104} ERROR - Failed to execute job 74 for task load_updated_data ('Location' object is not subscriptable; 18079)
[2023-07-03T16:36:52.633+0100] {local_task_job_runner.py:225} INFO - Task exited with return code 1
[2023-07-03T16:36:52.662+0100] {taskinstance.py:2653} INFO - 0 downstream tasks scheduled from follow-on schedule check
