[2023-07-03T18:20:07.659+0100] {taskinstance.py:1103} INFO - Dependencies all met for dep_context=non-requeueable deps ti=<TaskInstance: init_db.load_data manual__2023-07-03T17:17:47.102629+00:00 [queued]>
[2023-07-03T18:20:07.669+0100] {taskinstance.py:1103} INFO - Dependencies all met for dep_context=requeueable deps ti=<TaskInstance: init_db.load_data manual__2023-07-03T17:17:47.102629+00:00 [queued]>
[2023-07-03T18:20:07.670+0100] {taskinstance.py:1308} INFO - Starting attempt 1 of 1
[2023-07-03T18:20:07.683+0100] {taskinstance.py:1327} INFO - Executing <Task(PythonOperator): load_data> on 2023-07-03 17:17:47.102629+00:00
[2023-07-03T18:20:07.687+0100] {standard_task_runner.py:57} INFO - Started process 46779 to run task
[2023-07-03T18:20:07.690+0100] {standard_task_runner.py:84} INFO - Running: ['***', 'tasks', 'run', 'init_db', 'load_data', 'manual__2023-07-03T17:17:47.102629+00:00', '--job-id', '110', '--raw', '--subdir', '/home/haboubi/Desktop/api/API_weather/dags/init_db.py', '--cfg-path', '/tmp/tmpgf3ff5qb']
[2023-07-03T18:20:07.692+0100] {standard_task_runner.py:85} INFO - Job 110: Subtask load_data
[2023-07-03T18:20:07.763+0100] {task_command.py:410} INFO - Running <TaskInstance: init_db.load_data manual__2023-07-03T17:17:47.102629+00:00 [running]> on host haboubi-VivoBook-15-ASUS-Laptop-X540UB
[2023-07-03T18:20:07.879+0100] {taskinstance.py:1545} INFO - Exporting env vars: AIRFLOW_CTX_DAG_OWNER='***' AIRFLOW_CTX_DAG_ID='init_db' AIRFLOW_CTX_TASK_ID='load_data' AIRFLOW_CTX_EXECUTION_DATE='2023-07-03T17:17:47.102629+00:00' AIRFLOW_CTX_TRY_NUMBER='1' AIRFLOW_CTX_DAG_RUN_ID='manual__2023-07-03T17:17:47.102629+00:00'
[2023-07-03T18:20:07.962+0100] {logging_mixin.py:149} INFO - <class 'numpy.float64'>
[2023-07-03T18:20:07.971+0100] {taskinstance.py:1824} ERROR - Task failed with exception
Traceback (most recent call last):
  File "/home/haboubi/Desktop/api/API_weather/api_env/lib/python3.10/site-packages/airflow/operators/python.py", line 181, in execute
    return_value = self.execute_callable()
  File "/home/haboubi/Desktop/api/API_weather/api_env/lib/python3.10/site-packages/airflow/operators/python.py", line 198, in execute_callable
    return self.python_callable(*self.op_args, **self.op_kwargs)
  File "/home/haboubi/Desktop/api/API_weather/dags/init_db.py", line 23, in load_data
    locs=location_fill_liste()
  File "/home/haboubi/Desktop/api/API_weather/./dags/tools.py", line 58, in location_fill_liste
    loc=fill_location_data(loc)
  File "/home/haboubi/Desktop/api/API_weather/./dags/tools.py", line 45, in fill_location_data
    forc_data.append(Forcast_day(df_forc.iloc[i]))
  File "/home/haboubi/Desktop/api/API_weather/api_env/lib/python3.10/site-packages/pandas/core/indexing.py", line 1103, in __getitem__
    return self._getitem_axis(maybe_callable, axis=axis)
  File "/home/haboubi/Desktop/api/API_weather/api_env/lib/python3.10/site-packages/pandas/core/indexing.py", line 1656, in _getitem_axis
    self._validate_integer(key, axis)
  File "/home/haboubi/Desktop/api/API_weather/api_env/lib/python3.10/site-packages/pandas/core/indexing.py", line 1589, in _validate_integer
    raise IndexError("single positional indexer is out-of-bounds")
IndexError: single positional indexer is out-of-bounds
[2023-07-03T18:20:07.988+0100] {taskinstance.py:1345} INFO - Marking task as FAILED. dag_id=init_db, task_id=load_data, execution_date=20230703T171747, start_date=20230703T172007, end_date=20230703T172007
[2023-07-03T18:20:08.000+0100] {standard_task_runner.py:104} ERROR - Failed to execute job 110 for task load_data (single positional indexer is out-of-bounds; 46779)
[2023-07-03T18:20:08.022+0100] {local_task_job_runner.py:225} INFO - Task exited with return code 1
[2023-07-03T18:20:08.063+0100] {taskinstance.py:2653} INFO - 0 downstream tasks scheduled from follow-on schedule check
