[2023-07-03T16:24:36.494+0100] {taskinstance.py:1103} INFO - Dependencies all met for dep_context=non-requeueable deps ti=<TaskInstance: updated_day_hist.trigger_db scheduled__2023-07-01T00:00:00+00:00 [queued]>
[2023-07-03T16:24:36.503+0100] {taskinstance.py:1103} INFO - Dependencies all met for dep_context=requeueable deps ti=<TaskInstance: updated_day_hist.trigger_db scheduled__2023-07-01T00:00:00+00:00 [queued]>
[2023-07-03T16:24:36.503+0100] {taskinstance.py:1308} INFO - Starting attempt 2 of 3
[2023-07-03T16:24:36.516+0100] {taskinstance.py:1327} INFO - Executing <Task(PythonOperator): trigger_db> on 2023-07-01 00:00:00+00:00
[2023-07-03T16:24:36.521+0100] {standard_task_runner.py:57} INFO - Started process 14493 to run task
[2023-07-03T16:24:36.525+0100] {standard_task_runner.py:84} INFO - Running: ['***', 'tasks', 'run', 'updated_day_hist', 'trigger_db', 'scheduled__2023-07-01T00:00:00+00:00', '--job-id', '48', '--raw', '--subdir', '/home/haboubi/Desktop/api/API_weather/dags/update_day_hist.py', '--cfg-path', '/tmp/tmpjxjee93x']
[2023-07-03T16:24:36.526+0100] {standard_task_runner.py:85} INFO - Job 48: Subtask trigger_db
[2023-07-03T16:24:36.590+0100] {task_command.py:410} INFO - Running <TaskInstance: updated_day_hist.trigger_db scheduled__2023-07-01T00:00:00+00:00 [running]> on host haboubi-VivoBook-15-ASUS-Laptop-X540UB
[2023-07-03T16:24:36.719+0100] {taskinstance.py:1545} INFO - Exporting env vars: AIRFLOW_CTX_DAG_OWNER='haboubi' AIRFLOW_CTX_DAG_ID='updated_day_hist' AIRFLOW_CTX_TASK_ID='trigger_db' AIRFLOW_CTX_EXECUTION_DATE='2023-07-01T00:00:00+00:00' AIRFLOW_CTX_TRY_NUMBER='2' AIRFLOW_CTX_DAG_RUN_ID='scheduled__2023-07-01T00:00:00+00:00'
[2023-07-03T16:24:36.720+0100] {taskinstance.py:1824} ERROR - Task failed with exception
Traceback (most recent call last):
  File "/home/haboubi/Desktop/api/API_weather/api_env/lib/python3.10/site-packages/airflow/operators/python.py", line 181, in execute
    return_value = self.execute_callable()
  File "/home/haboubi/Desktop/api/API_weather/api_env/lib/python3.10/site-packages/airflow/operators/python.py", line 198, in execute_callable
    return self.python_callable(*self.op_args, **self.op_kwargs)
  File "/home/haboubi/Desktop/api/API_weather/dags/update_day_hist.py", line 19, in trigger_database_dag
    info=trigger_database()
TypeError: trigger_database() missing 1 required positional argument: 'locations'
[2023-07-03T16:24:36.736+0100] {taskinstance.py:1345} INFO - Marking task as UP_FOR_RETRY. dag_id=updated_day_hist, task_id=trigger_db, execution_date=20230701T000000, start_date=20230703T152436, end_date=20230703T152436
[2023-07-03T16:24:36.745+0100] {standard_task_runner.py:104} ERROR - Failed to execute job 48 for task trigger_db (trigger_database() missing 1 required positional argument: 'locations'; 14493)
[2023-07-03T16:24:36.777+0100] {local_task_job_runner.py:225} INFO - Task exited with return code 1
[2023-07-03T16:24:36.807+0100] {taskinstance.py:2653} INFO - 0 downstream tasks scheduled from follow-on schedule check
