[2023-06-30T02:36:43.023+0100] {taskinstance.py:1103} INFO - Dependencies all met for dep_context=non-requeueable deps ti=<TaskInstance: first_python_dag.first_task_python manual__2023-06-30T01:17:01.114903+00:00 [queued]>
[2023-06-30T02:36:43.031+0100] {taskinstance.py:1103} INFO - Dependencies all met for dep_context=requeueable deps ti=<TaskInstance: first_python_dag.first_task_python manual__2023-06-30T01:17:01.114903+00:00 [queued]>
[2023-06-30T02:36:43.031+0100] {taskinstance.py:1308} INFO - Starting attempt 5 of 10
[2023-06-30T02:36:43.042+0100] {taskinstance.py:1327} INFO - Executing <Task(PythonOperator): first_task_python> on 2023-06-30 01:17:01.114903+00:00
[2023-06-30T02:36:43.045+0100] {standard_task_runner.py:57} INFO - Started process 11917 to run task
[2023-06-30T02:36:43.048+0100] {standard_task_runner.py:84} INFO - Running: ['airflow', 'tasks', 'run', 'first_python_dag', 'first_task_python', 'manual__2023-06-30T01:17:01.114903+00:00', '--job-id', '8', '--raw', '--subdir', '/home/haboubi/Desktop/api/API_weather/dags/dag_create_py.py', '--cfg-path', '/tmp/tmpue2fhwl5']
[2023-06-30T02:36:43.050+0100] {standard_task_runner.py:85} INFO - Job 8: Subtask first_task_python
[2023-06-30T02:36:43.097+0100] {task_command.py:410} INFO - Running <TaskInstance: first_python_dag.first_task_python manual__2023-06-30T01:17:01.114903+00:00 [running]> on host haboubi-VivoBook-15-ASUS-Laptop-X540UB
[2023-06-30T02:36:43.169+0100] {taskinstance.py:1545} INFO - Exporting env vars: AIRFLOW_CTX_DAG_OWNER='haboubi' AIRFLOW_CTX_DAG_ID='first_python_dag' AIRFLOW_CTX_TASK_ID='first_task_python' AIRFLOW_CTX_EXECUTION_DATE='2023-06-30T01:17:01.114903+00:00' AIRFLOW_CTX_TRY_NUMBER='5' AIRFLOW_CTX_DAG_RUN_ID='manual__2023-06-30T01:17:01.114903+00:00'
[2023-06-30T02:36:43.170+0100] {taskinstance.py:1824} ERROR - Task failed with exception
Traceback (most recent call last):
  File "/home/haboubi/Desktop/api/API_weather/api_env/lib/python3.10/site-packages/airflow/operators/python.py", line 181, in execute
    return_value = self.execute_callable()
  File "/home/haboubi/Desktop/api/API_weather/api_env/lib/python3.10/site-packages/airflow/operators/python.py", line 198, in execute_callable
    return self.python_callable(*self.op_args, **self.op_kwargs)
  File "/home/haboubi/Desktop/api/API_weather/dags/dag_create_py.py", line 14, in greet
    name=ti1.xcomp_pull(task_ids='get_name')
NameError: name 'ti1' is not defined
[2023-06-30T02:36:43.174+0100] {taskinstance.py:1345} INFO - Marking task as UP_FOR_RETRY. dag_id=first_python_dag, task_id=first_task_python, execution_date=20230630T011701, start_date=20230630T013643, end_date=20230630T013643
[2023-06-30T02:36:43.182+0100] {standard_task_runner.py:104} ERROR - Failed to execute job 8 for task first_task_python (name 'ti1' is not defined; 11917)
[2023-06-30T02:36:43.221+0100] {local_task_job_runner.py:225} INFO - Task exited with return code 1
[2023-06-30T02:36:43.242+0100] {taskinstance.py:2653} INFO - 0 downstream tasks scheduled from follow-on schedule check
