[2023-06-30T02:38:46.032+0100] {taskinstance.py:1103} INFO - Dependencies all met for dep_context=non-requeueable deps ti=<TaskInstance: first_python_dag.first_task_python manual__2023-06-30T01:17:01.114903+00:00 [queued]>
[2023-06-30T02:38:46.047+0100] {taskinstance.py:1103} INFO - Dependencies all met for dep_context=requeueable deps ti=<TaskInstance: first_python_dag.first_task_python manual__2023-06-30T01:17:01.114903+00:00 [queued]>
[2023-06-30T02:38:46.048+0100] {taskinstance.py:1308} INFO - Starting attempt 6 of 10
[2023-06-30T02:38:46.065+0100] {taskinstance.py:1327} INFO - Executing <Task(PythonOperator): first_task_python> on 2023-06-30 01:17:01.114903+00:00
[2023-06-30T02:38:46.067+0100] {standard_task_runner.py:57} INFO - Started process 12265 to run task
[2023-06-30T02:38:46.070+0100] {standard_task_runner.py:84} INFO - Running: ['airflow', 'tasks', 'run', 'first_python_dag', 'first_task_python', 'manual__2023-06-30T01:17:01.114903+00:00', '--job-id', '9', '--raw', '--subdir', '/home/haboubi/Desktop/api/API_weather/dags/dag_create_py.py', '--cfg-path', '/tmp/tmpe3kjbub8']
[2023-06-30T02:38:46.072+0100] {standard_task_runner.py:85} INFO - Job 9: Subtask first_task_python
[2023-06-30T02:38:46.105+0100] {task_command.py:410} INFO - Running <TaskInstance: first_python_dag.first_task_python manual__2023-06-30T01:17:01.114903+00:00 [running]> on host haboubi-VivoBook-15-ASUS-Laptop-X540UB
[2023-06-30T02:38:46.169+0100] {taskinstance.py:1545} INFO - Exporting env vars: AIRFLOW_CTX_DAG_OWNER='haboubi' AIRFLOW_CTX_DAG_ID='first_python_dag' AIRFLOW_CTX_TASK_ID='first_task_python' AIRFLOW_CTX_EXECUTION_DATE='2023-06-30T01:17:01.114903+00:00' AIRFLOW_CTX_TRY_NUMBER='6' AIRFLOW_CTX_DAG_RUN_ID='manual__2023-06-30T01:17:01.114903+00:00'
[2023-06-30T02:38:46.170+0100] {taskinstance.py:1824} ERROR - Task failed with exception
Traceback (most recent call last):
  File "/home/haboubi/Desktop/api/API_weather/api_env/lib/python3.10/site-packages/airflow/operators/python.py", line 181, in execute
    return_value = self.execute_callable()
  File "/home/haboubi/Desktop/api/API_weather/api_env/lib/python3.10/site-packages/airflow/operators/python.py", line 198, in execute_callable
    return self.python_callable(*self.op_args, **self.op_kwargs)
TypeError: greet() missing 1 required positional argument: 'ti1'
[2023-06-30T02:38:46.173+0100] {taskinstance.py:1345} INFO - Marking task as UP_FOR_RETRY. dag_id=first_python_dag, task_id=first_task_python, execution_date=20230630T011701, start_date=20230630T013846, end_date=20230630T013846
[2023-06-30T02:38:46.182+0100] {standard_task_runner.py:104} ERROR - Failed to execute job 9 for task first_task_python (greet() missing 1 required positional argument: 'ti1'; 12265)
[2023-06-30T02:38:46.202+0100] {local_task_job_runner.py:225} INFO - Task exited with return code 1
[2023-06-30T02:38:46.220+0100] {taskinstance.py:2653} INFO - 0 downstream tasks scheduled from follow-on schedule check
