[2023-07-05T11:14:35.164+0100] {taskinstance.py:1103} INFO - Dependencies all met for dep_context=non-requeueable deps ti=<TaskInstance: update_current_data_10.load_current_data scheduled__2023-05-07T20:00:00+00:00 [queued]>
[2023-07-05T11:14:35.176+0100] {taskinstance.py:1103} INFO - Dependencies all met for dep_context=requeueable deps ti=<TaskInstance: update_current_data_10.load_current_data scheduled__2023-05-07T20:00:00+00:00 [queued]>
[2023-07-05T11:14:35.176+0100] {taskinstance.py:1308} INFO - Starting attempt 2 of 3
[2023-07-05T11:14:35.191+0100] {taskinstance.py:1327} INFO - Executing <Task(PythonOperator): load_current_data> on 2023-05-07 20:00:00+00:00
[2023-07-05T11:14:35.195+0100] {standard_task_runner.py:57} INFO - Started process 81327 to run task
[2023-07-05T11:14:35.198+0100] {standard_task_runner.py:84} INFO - Running: ['***', 'tasks', 'run', 'update_current_data_10', 'load_current_data', 'scheduled__2023-05-07T20:00:00+00:00', '--job-id', '870', '--raw', '--subdir', '/home/haboubi/Desktop/api/API_weather/dags/update_current_dags.py', '--cfg-path', '/tmp/tmptkrmj3bd']
[2023-07-05T11:14:35.202+0100] {standard_task_runner.py:85} INFO - Job 870: Subtask load_current_data
[2023-07-05T11:14:35.284+0100] {task_command.py:410} INFO - Running <TaskInstance: update_current_data_10.load_current_data scheduled__2023-05-07T20:00:00+00:00 [running]> on host haboubi-VivoBook-15-ASUS-Laptop-X540UB
[2023-07-05T11:14:35.408+0100] {taskinstance.py:1545} INFO - Exporting env vars: AIRFLOW_CTX_DAG_OWNER='haboubi' AIRFLOW_CTX_DAG_ID='update_current_data_10' AIRFLOW_CTX_TASK_ID='load_current_data' AIRFLOW_CTX_EXECUTION_DATE='2023-05-07T20:00:00+00:00' AIRFLOW_CTX_TRY_NUMBER='2' AIRFLOW_CTX_DAG_RUN_ID='scheduled__2023-05-07T20:00:00+00:00'
[2023-07-05T11:14:35.430+0100] {logging_mixin.py:149} INFO - ['Paris', datetime.date(2023, 7, 4)]
[2023-07-05T11:14:35.464+0100] {taskinstance.py:1824} ERROR - Task failed with exception
Traceback (most recent call last):
  File "/home/haboubi/Desktop/api/API_weather/api_env/lib/python3.10/site-packages/airflow/operators/python.py", line 181, in execute
    return_value = self.execute_callable()
  File "/home/haboubi/Desktop/api/API_weather/api_env/lib/python3.10/site-packages/airflow/operators/python.py", line 198, in execute_callable
    return self.python_callable(*self.op_args, **self.op_kwargs)
  File "/home/haboubi/Desktop/api/API_weather/dags/update_current_dags.py", line 55, in load_updated_data_db
    loc=update_location_entite(loc)
  File "/home/haboubi/Desktop/api/API_weather/dags/update_current_dags.py", line 40, in update_location_entite
    type(datetime(current.date))
TypeError: 'str' object cannot be interpreted as an integer
[2023-07-05T11:14:35.481+0100] {taskinstance.py:1345} INFO - Marking task as UP_FOR_RETRY. dag_id=update_current_data_10, task_id=load_current_data, execution_date=20230507T200000, start_date=20230705T101435, end_date=20230705T101435
[2023-07-05T11:14:35.494+0100] {standard_task_runner.py:104} ERROR - Failed to execute job 870 for task load_current_data ('str' object cannot be interpreted as an integer; 81327)
[2023-07-05T11:14:35.531+0100] {local_task_job_runner.py:225} INFO - Task exited with return code 1
[2023-07-05T11:14:35.570+0100] {taskinstance.py:2653} INFO - 0 downstream tasks scheduled from follow-on schedule check
